Traceback (most recent call last):
  File "/homeappl/home/aliagadi/appl_taito/miniconda3/envs/b36/lib/python3.6/site-packages/pandas/io/sql.py", line 1378, in execute
    cur.execute(*args)
sqlite3.OperationalError: disk I/O error

During handling of the above exception, another exception occurred:

Traceback (most recent call last):
  File "ungrib_avgtsfc.py", line 58, in <module>
    run_row = wrf_management.run_utilities.get_run_row()
  File "/homeappl/home/aliagadi/saltena_2018/wrf_management/wrf_management/run_utilities.py", line 21, in get_run_row
    run_row = pd.read_sql(sql, con).iloc[0]
  File "/homeappl/home/aliagadi/appl_taito/miniconda3/envs/b36/lib/python3.6/site-packages/pandas/io/sql.py", line 381, in read_sql
    chunksize=chunksize)
  File "/homeappl/home/aliagadi/appl_taito/miniconda3/envs/b36/lib/python3.6/site-packages/pandas/io/sql.py", line 1413, in read_query
    cursor = self.execute(*args)
  File "/homeappl/home/aliagadi/appl_taito/miniconda3/envs/b36/lib/python3.6/site-packages/pandas/io/sql.py", line 1390, in execute
    raise_with_traceback(ex)
  File "/homeappl/home/aliagadi/appl_taito/miniconda3/envs/b36/lib/python3.6/site-packages/pandas/compat/__init__.py", line 404, in raise_with_traceback
    raise exc.with_traceback(traceback)
  File "/homeappl/home/aliagadi/appl_taito/miniconda3/envs/b36/lib/python3.6/site-packages/pandas/io/sql.py", line 1378, in execute
    cur.execute(*args)
pandas.io.sql.DatabaseError: Execution failed on sql '
    select * from 'runs_table' where run_name='run_2019_02_20'
    ': disk I/O error
